<?xml version="1.0" ?>
<robot name="panda" xmlns:xacro="http://www.ros.org/wiki/xacro">
	<link name="world"/>
	<link name="panda_link0">
		<visual>
			<geometry>
				<mesh filename="package://pick_place_moveit2/panda_description/meshes/visual/link0.dae"/>
            </geometry>
        </visual>
        <collision>
            <geometry>
                <mesh filename="package://pick_place_moveit2/panda_description/meshes/collision/link0.stl"/>
            </geometry>
        </collision>
        <inertial>
          <origin xyz="0 0 0" rpy="0 0 0" />
          <mass value="3.06"/>
          <inertia ixx="0.3" ixy="0.0" ixz="0.0" iyy="0.3" iyz="0.0" izz="0.3" />
        </inertial>
	</link>
	<gazebo reference="panda_link0">
        <material>Gazebo/Grey</material>
        <mu1>0.2</mu1>
        <mu2>0.2</mu2>
        <selfCollide>True</selfCollide>
    </gazebo>
	<joint name="panda_joint0" type="fixed">
		<origin rpy="0 0 0" xyz="0 0 0"/>
		<parent link="world"/>
		<child link="panda_link0"/>
		<axis xyz="0 0 0" />
		<dynamics damping="1.0"/>
	</joint>
	<!-- end of panda link0 -->
	
    <link name="panda_link1">
        <visual>
            <geometry>
                <mesh filename="package://pick_place_moveit2/panda_description/meshes/visual/link1.dae" />
            </geometry>
        </visual>
        <collision>
            <geometry>
                <mesh filename="package://pick_place_moveit2/panda_description/meshes/collision/link1.stl" />
            </geometry>
        </collision>
        <inertial>
          <origin xyz="0 0 0" rpy="0 0 0" />
          <mass value="2.34"/>
          <inertia ixx="0.3" ixy="0.0" ixz="0.0" iyy="0.3" iyz="0.0" izz="0.3" />
        </inertial>        
    </link>
	<gazebo reference="panda_link1">
        <material>Gazebo/White</material>
        <mu1>0.2</mu1>
        <mu2>0.2</mu2>
        <selfCollide>True</selfCollide>
    </gazebo>  
    <joint name="panda_joint1" type="revolute">
        <safety_controller k_position="100.0" k_velocity="40.0" soft_lower_limit="-2.8973" soft_upper_limit="2.8973" />
        <origin rpy="0 0 0" xyz="0 0 0.333" />
        <parent link="panda_link0" />
        <child link="panda_link1" />
        <axis xyz="0 0 1" />
        <limit effort="87" lower="-2.9671" upper="2.9671" velocity="2.3925" />
        <dynamics damping="1.0"/>
    </joint>
    <!-- end of panda link1 -->
    
    <link name="panda_link2">
        <visual>
            <geometry>
                <mesh filename="package://pick_place_moveit2/panda_description/meshes/visual/link2.dae" />
            </geometry>
        </visual>
        <collision>
            <geometry>
                <mesh filename="package://pick_place_moveit2/panda_description/meshes/collision/link2.stl" />
            </geometry>
        </collision>
        <inertial>
          <origin xyz="0 0 0" rpy="0 0 0" />
          <mass value="2.36"/>
          <inertia ixx="0.3" ixy="0.0" ixz="0.0" iyy="0.3" iyz="0.0" izz="0.3" />
        </inertial>
    </link>
    <gazebo reference="panda_link2">
        <material>Gazebo/White</material>
        <mu1>0.2</mu1>
        <mu2>0.2</mu2>
        <selfCollide>True</selfCollide>
    </gazebo>
    <joint name="panda_joint2" type="revolute">
        <safety_controller k_position="100.0" k_velocity="40.0" soft_lower_limit="-1.7628" soft_upper_limit="1.7628" />
        <origin rpy="-1.57079632679 0 0" xyz="0 0 0" />
        <parent link="panda_link1" />
        <child link="panda_link2" />
        <axis xyz="0 0 1" />
        <limit effort="87" lower="-1.8326" upper="1.8326" velocity="2.3925" />
        <dynamics damping="1.0"/>
    </joint>
	<!-- end of panda link2-->
	
    <link name="panda_link3">
        <visual>
            <geometry>
                <mesh filename="package://pick_place_moveit2/panda_description/meshes/visual/link3.dae" />
            </geometry>
        </visual>
        <collision>
            <geometry>
                <mesh filename="package://pick_place_moveit2/panda_description/meshes/collision/link3.stl" />
            </geometry>
        </collision>
        <inertial>
          <origin xyz="0 0 0" rpy="0 0 0" />
          <mass value="2.38"/>
          <inertia ixx="0.3" ixy="0.0" ixz="0.0" iyy="0.3" iyz="0.0" izz="0.3" />
        </inertial>
    </link>
    <gazebo reference="panda_link3">
        <material>Gazebo/White</material>
        <mu1>0.2</mu1>
        <mu2>0.2</mu2>
        <selfCollide>True</selfCollide>
    </gazebo>  
    <joint name="panda_joint3" type="revolute">
        <safety_controller k_position="100.0" k_velocity="40.0" soft_lower_limit="-2.8973" soft_upper_limit="2.8973" />
        <origin rpy="1.57079632679 0 0" xyz="0 -0.316 0" />
        <parent link="panda_link2" />
        <child link="panda_link3" />
        <axis xyz="0 0 1" />
        <limit effort="87" lower="-2.9671" upper="2.9671" velocity="2.3925" />
        <dynamics damping="1.0"/>
    </joint>
    <!-- end of panda link 3 -->
    
    <link name="panda_link4">
        <visual>
            <geometry>
                <mesh filename="package://pick_place_moveit2/panda_description/meshes/visual/link4.dae" />
            </geometry>
        </visual>
        <collision>
            <geometry>
                <mesh filename="package://pick_place_moveit2/panda_description/meshes/collision/link4.stl" />
            </geometry>
        </collision>
        <inertial>
          <origin xyz="0 0 0" rpy="0 0 0" />
          <mass value="2.43"/>
          <inertia ixx="0.3" ixy="0.0" ixz="0.0" iyy="0.3" iyz="0.0" izz="0.3" />
        </inertial>
    </link>
    <gazebo reference="panda_link4">
        <material>Gazebo/White</material>
        <mu1>0.2</mu1>
        <mu2>0.2</mu2>
        <selfCollide>True</selfCollide>
    </gazebo>  
    <joint name="panda_joint4" type="revolute">
        <safety_controller k_position="100.0" k_velocity="40.0" soft_lower_limit="-3.0718" soft_upper_limit="0.0175" />
        <origin rpy="1.57079632679 0 0" xyz="0.0825 0 0" />
        <parent link="panda_link3" />
        <child link="panda_link4" />
        <axis xyz="0 0 1" />
        <limit effort="87" lower="-3.1416" upper="0.0873" velocity="2.3925" />
        <dynamics damping="1.0"/>
    </joint>
    <!-- end of panda link4 -->
    
    <link name="panda_link5">
        <visual>
            <geometry>
                <mesh filename="package://pick_place_moveit2/panda_description/meshes/visual/link5.dae" />
            </geometry>
        </visual>
        <collision>
            <geometry>
                <mesh filename="package://pick_place_moveit2/panda_description/meshes/collision/link5.stl" />
            </geometry>
        </collision>
        <inertial>
          <origin xyz="0 0 0" rpy="0 0 0" />
          <mass value="3.5"/>
          <inertia ixx="0.3" ixy="0.0" ixz="0.0" iyy="0.3" iyz="0.0" izz="0.3" />
        </inertial>
    </link>
    <gazebo reference="panda_link5">
        <material>Gazebo/White</material>
        <mu1>0.2</mu1>
        <mu2>0.2</mu2>
        <selfCollide>True</selfCollide>
    </gazebo>  
    <joint name="panda_joint5" type="revolute">
        <safety_controller k_position="100.0" k_velocity="40.0" soft_lower_limit="-2.8973" soft_upper_limit="2.8973" />
        <origin rpy="-1.57079632679 0 0" xyz="-0.0825 0.384 0" />
        <parent link="panda_link4" />
        <child link="panda_link5" />
        <axis xyz="0 0 1" />
        <limit effort="12" lower="-2.9671" upper="2.9671" velocity="2.8710" />
        <dynamics damping="1.0"/>
    </joint>
    <!-- end of link 5 -->
    
    <link name="panda_link6">
        <visual>
            <geometry>
                <mesh filename="package://pick_place_moveit2/panda_description/meshes/visual/link6.dae" />
            </geometry>
        </visual>
        <collision>
            <geometry>
                <mesh filename="package://pick_place_moveit2/panda_description/meshes/collision/link6.stl" />
            </geometry>
        </collision>
        <inertial>
          <origin xyz="0 0 0" rpy="0 0 0" />
          <mass value="1.47"/>
          <inertia ixx="0.3" ixy="0.0" ixz="0.0" iyy="0.3" iyz="0.0" izz="0.3" />
        </inertial>
    </link>
    <gazebo reference="panda_link6">
        <material>Gazebo/White</material>
        <mu1>0.2</mu1>
        <mu2>0.2</mu2>
        <selfCollide>True</selfCollide>
    </gazebo> 
    <joint name="panda_joint6" type="revolute">
        <safety_controller k_position="100.0" k_velocity="40.0" soft_lower_limit="-0.0175" soft_upper_limit="3.7525" />
        <origin rpy="1.57079632679 0 0" xyz="0 0 0" />
        <parent link="panda_link5" />
        <child link="panda_link6" />
        <axis xyz="0 0 1" />
        <limit effort="12" lower="-0.0873" upper="3.8223" velocity="2.8710" />
        <dynamics damping="1.0"/>
    </joint> 
    <!-- end of link 6 -->
    
    <link name="panda_link7">
        <visual>
            <geometry>
                <mesh filename="package://pick_place_moveit2/panda_description/meshes/visual/link7.dae" />
            </geometry>
        </visual>
        <collision>
            <geometry>
                <mesh filename="package://pick_place_moveit2/panda_description/meshes/collision/link7.stl" />
            </geometry>
        </collision>
        <inertial>
          <origin xyz="0 0 0" rpy="0 0 0" />
          <mass value="0.45"/>
          <inertia ixx="0.3" ixy="0.0" ixz="0.0" iyy="0.3" iyz="0.0" izz="0.3" />
        </inertial>
    </link>
    <gazebo reference="panda_link7">
        <material>Gazebo/Grey</material>
        <mu1>0.2</mu1>
        <mu2>0.2</mu2>
        <selfCollide>True</selfCollide>
    </gazebo> 
    <joint name="panda_joint7" type="revolute">
        <safety_controller k_position="100.0" k_velocity="40.0" soft_lower_limit="-2.8973" soft_upper_limit="2.8973" />
        <origin rpy="1.57079632679 0 0" xyz="0.088 0 0" />
        <parent link="panda_link6" />
        <child link="panda_link7" />
        <axis xyz="0 0 1" />
        <limit effort="12" lower="-2.9671" upper="2.9671" velocity="2.8710" />
        <dynamics damping="1.0"/>
    </joint>   
    <!-- end of link 7 -->

    <link name="panda_link8" >
        <!--inertial>
          <origin xyz="0 0 0" rpy="0 0 0" />
          <mass value="0.45"/>
          <inertia ixx="0.3" ixy="0.0" ixz="0.0" iyy="0.3" iyz="0.0" izz="0.3" />
        </inertial-->
    </link>
    <gazebo reference="panda_link8">
        <material>Gazebo/Grey</material>
        <mu1>0.2</mu1>
        <mu2>0.2</mu2>
        <selfCollide>True</selfCollide>
    </gazebo> 
    <joint name="panda_joint8" type="fixed">
        <origin rpy="0 0 0" xyz="0 0 0.107" />
        <parent link="panda_link7" />
        <child link="panda_link8" />
        <axis xyz="0 0 0" />
        <dynamics damping="1.0"/>
    </joint>
    <!-- end of link8 -->
    
    <link name="panda_hand">
        <visual>
            <geometry>
                <mesh filename="package://pick_place_moveit2/panda_description/meshes/visual/hand.dae" />
            </geometry>
        </visual>
        <collision>
            <geometry>
                <mesh filename="package://pick_place_moveit2/panda_description/meshes/collision/hand.stl" />
            </geometry>
        </collision>
      <inertial>
        <origin xyz="0 0 0" rpy="0 0 0" />
        <mass value="0.68" />
        <inertia ixx="0.1" ixy="0.0" ixz="0.0" iyy="0.1" iyz="0.0" izz="0.1" />
      </inertial>
    </link>
    <gazebo reference="panda_hand">
        <material>Gazebo/Grey</material>
        <mu1>0.2</mu1>
        <mu2>0.2</mu2>
        <selfCollide>True</selfCollide>
    </gazebo> 
    <joint name="panda_hand_joint" type="fixed">
        <parent link="panda_link8" />
        <child link="panda_hand" />
        <origin rpy="0 0 -0.785398163397" xyz="0 0 0" />
		<dynamics damping="1.0"/>
    </joint>
    <!-- end of panda hand --> 
    
    <link name="panda_leftfinger">
        <visual>
            <geometry>
                <mesh filename="package://pick_place_moveit2/panda_description/meshes/visual/finger.dae" />
            </geometry>
        </visual>
        <collision>
            <geometry>
                <mesh filename="package://pick_place_moveit2/panda_description/meshes/collision/finger.stl" />
            </geometry>
        </collision>
      <inertial>
        <origin xyz="0 0 0" rpy="0 0 0" />
        <mass value="0.01" />
        <inertia ixx="0.1" ixy="0.0" ixz="0.0" iyy="0.1" iyz="0.0" izz="0.1" />
      </inertial>
    </link>
    <gazebo reference="panda_leftfinger">
        <material>Gazebo/Grey</material>
        <mu1>0.2</mu1>
        <mu2>0.2</mu2>
        <selfCollide>True</selfCollide>
    </gazebo> 
    <joint name="panda_finger_joint1" type="prismatic">
        <parent link="panda_hand" />
        <child link="panda_leftfinger" />
        <origin rpy="0 0 0" xyz="0 0 0.0584" />
        <axis xyz="0 1 0" />
        <limit effort="20" lower="0.0" upper="0.04" velocity="0.2" />
    </joint>
	<!-- end of left finger -->
	
    <link name="panda_rightfinger">
        <visual>
            <origin rpy="0 0 3.14159265359" xyz="0 0 0" />
            <geometry>
                <mesh filename="package://pick_place_moveit2/panda_description/meshes/visual/finger.dae" />
            </geometry>
        </visual>
        <collision>
            <origin rpy="0 0 3.14159265359" xyz="0 0 0" />
            <geometry>
                <mesh filename="package://pick_place_moveit2/panda_description/meshes/collision/finger.stl" />
            </geometry>
        </collision>
      <inertial>
        <origin xyz="0 0 0" rpy="0 0 0" />
        <mass value="0.01" />
        <inertia ixx="0.1" ixy="0.0" ixz="0.0" iyy="0.1" iyz="0.0" izz="0.1" />
      </inertial>
    </link>
    <gazebo reference="panda_rightfinger">
        <material>Gazebo/Grey</material>
        <mu1>0.2</mu1>
        <mu2>0.2</mu2>
        <selfCollide>True</selfCollide>
    </gazebo> 
    <joint name="panda_finger_joint2" type="prismatic">
        <parent link="panda_hand" />
        <child link="panda_rightfinger" />
        <origin rpy="0 0 0" xyz="0 0 0.0584" />
        <axis xyz="0 -1 0" />
        <limit effort="20" lower="0.0" upper="0.04" velocity="0.2" />
        <mimic joint="panda_finger_joint1" />
    </joint >
    <!-- end of right finger -->
    
    <!-- end of robot -->

  <!-- ros_control plugin -->
  <gazebo>
    <plugin filename="libgazebo_ros2_control.so" name="gazebo_ros2_control">
      <robot_sim_type>gazebo_ros2_control/GazeboSystem</robot_sim_type>
      <parameters>$(find pick_place_moveit2)/config/gazebo_panda_controllers.yaml</parameters>
    </plugin>
  </gazebo>
          
</robot>
